Workbook

Sheet Orders
A1: Order_ID | B1: Order_Date | C1: Customer_ID | D1: Product_ID | E1: Quantity | F1: Unit_Price | G1: Discount_% | H1: Payment_Mode | I1: Region | J1: Salesperson | K1: Gross Amount | L1: Discount Amount | M1: Net Sales | N1: Sales Category | O1: Order Priority | P1: Customer_ID (Num) | Q1: Product_ID (Num) | R1: Salesperson (Cleaned) | S1: Region (Cleaned) | T1: Product Name | U1: Category | V1: Brand | W1: Supplier | X1: Product Rating
A2: ORD1001 | B2: 46037 | C2: C043 | D2: P107 | E2: 2 | F2: 2200 | G2: 0.12 | H2: Cash | I2: East | J2: Priya | K2: =PRODUCT(E2,F2) -> 4400 | L2: =PRODUCT(K2,G2) -> 528 | M2: =K2-L2 -> 3872 | N2: =IF(M2>=50000,"High Value",IF(M2>=20000,"Medium Value","Low Value")) -> Low Value | O2: =IF(AND(E2>=5,G2>=15%),"High",IF(OR(E2>=3,G2>=10%),"Medium","Low")) -> Medium | P2: =RIGHT(C2,3) -> 043 | Q2: =RIGHT(D2,3) -> 107 | R2: =PROPER(TRIM(J2)) -> Priya | S2: =TRIM(PROPER(I2)) -> East | T2: =IFERROR(VLOOKUP(D2,Product_Reference!$A$1:$F$26,2,0),"Not Found!!") -> USB-C Hub | U2: =IFERROR(VLOOKUP(D2,Product_Reference!$A$1:$F$26,3,0),"Not Found!!") -> Accessories | V2: =IFERROR(VLOOKUP(D2,Product_Reference!$A$1:$F$26,4,0),"Not Found!!") -> ConnectPro | W2: =IFERROR(VLOOKUP(D2,Product_Reference!$A$1:$F$26,5,0),"Not Found!!") -> PQR Ltd | X2: =IFERROR(VLOOKUP(D2,Product_Reference!$A$1:$F$26,6,0),"Not Found!!") -> 4.3 | AA2: 1. Calculate the total number of orders in the dataset. | AH2: 11. Create a Gross Amount column. Calculate the gross amount for every order using Quantity and Unit Price.
A3: ORD1002 | B3: 46097 | C3: C024 | D3: P119 | E3: 3 | F3: 12500 | G3: 0.08 | H3: UPI | I3: South | J3: Amit | K3: =PRODUCT(E3,F3) -> 37500 | L3: =PRODUCT(K3,G3) -> 3000 | M3: =K3-L3 -> 34500 | N3: =IF(M3>=50000,"High Value",IF(M3>=20000,"Medium Value","Low Value")) -> Medium Value | O3: =IF(AND(E3>=5,G3>=15%),"High",IF(OR(E3>=3,G3>=10%),"Medium","Low")) -> Medium | P3: =RIGHT(C3,3) -> 024 | Q3: =RIGHT(D3,3) -> 119 | R3: =PROPER(TRIM(J3)) -> Amit | S3: =TRIM(PROPER(I3)) -> South | T3: =IFERROR(VLOOKUP(D3,Product_Reference!$A$1:$F$26,2,0),"Not Found!!") -> Office Chair | U3: =IFERROR(VLOOKUP(D3,Product_Reference!$A$1:$F$26,3,0),"Not Found!!") -> Furniture | V3: =IFERROR(VLOOKUP(D3,Product_Reference!$A$1:$F$26,4,0),"Not Found!!") -> ComfortPro | W3: =IFERROR(VLOOKUP(D3,Product_Reference!$A$1:$F$26,5,0),"Not Found!!") -> ABC Ltd | X3: =IFERROR(VLOOKUP(D3,Product_Reference!$A$1:$F$26,6,0),"Not Found!!") -> 4.2 | AD3: Cash | AF3: East
A4: ORD1003 | B4: 46110 | C4: C044 | D4: P122 | E4: 2 | F4: 5500 | G4: 0.05 | H4: Net Banking | I4: West | J4: Sneha | K4: =PRODUCT(E4,F4) -> 11000 | L4: =PRODUCT(K4,G4) -> 550 | M4: =K4-L4 -> 10450 | N4: =IF(M4>=50000,"High Value",IF(M4>=20000,"Medium Value","Low Value")) -> Low Value | O4: =IF(AND(E4>=5,G4>=15%),"High",IF(OR(E4>=3,G4>=10%),"Medium","Low")) -> Low | P4: =RIGHT(C4,3) -> 044 | Q4: =RIGHT(D4,3) -> 122 | R4: =PROPER(TRIM(J4)) -> Sneha | S4: =TRIM(PROPER(I4)) -> West | T4: =IFERROR(VLOOKUP(D4,Product_Reference!$A$1:$F$26,2,0),"Not Found!!") -> Router AX1800 | U4: =IFERROR(VLOOKUP(D4,Product_Reference!$A$1:$F$26,3,0),"Not Found!!") -> Networking | V4: =IFERROR(VLOOKUP(D4,Product_Reference!$A$1:$F$26,4,0),"Not Found!!") -> NetLink | W4: =IFERROR(VLOOKUP(D4,Product_Reference!$A$1:$F$26,5,0),"Not Found!!") -> ABC Ltd | X4: =IFERROR(VLOOKUP(D4,Product_Reference!$A$1:$F$26,6,0),"Not Found!!") -> 4.5 | AA4: Total Orders | AB4: =COUNTA(A2:A151) -> 150 | AD4: UPI | AF4: South | AH4: 12. Create a Discount Amount column. Calculate the discount amount for every order.
A5: ORD1004 | B5: 46080 | C5: C022 | D5: P121 | E5: 1 | F5: 30000 | G5: 0.1 | H5: UPI | I5: East | J5: Rahul | K5: =PRODUCT(E5,F5) -> 30000 | L5: =PRODUCT(K5,G5) -> 3000 | M5: =K5-L5 -> 27000 | N5: =IF(M5>=50000,"High Value",IF(M5>=20000,"Medium Value","Low Value")) -> Medium Value | O5: =IF(AND(E5>=5,G5>=15%),"High",IF(OR(E5>=3,G5>=10%),"Medium","Low")) -> Medium | P5: =RIGHT(C5,3) -> 022 | Q5: =RIGHT(D5,3) -> 121 | R5: =PROPER(TRIM(J5)) -> Rahul | S5: =TRIM(PROPER(I5)) -> East | T5: =IFERROR(VLOOKUP(D5,Product_Reference!$A$1:$F$26,2,0),"Not Found!!") -> Portable Projector | U5: =IFERROR(VLOOKUP(D5,Product_Reference!$A$1:$F$26,3,0),"Not Found!!") -> Electronics | V5: =IFERROR(VLOOKUP(D5,Product_Reference!$A$1:$F$26,4,0),"Not Found!!") -> ViewMax | W5: =IFERROR(VLOOKUP(D5,Product_Reference!$A$1:$F$26,5,0),"Not Found!!") -> PQR Ltd | X5: =IFERROR(VLOOKUP(D5,Product_Reference!$A$1:$F$26,6,0),"Not Found!!") -> 4.1 | AD5: Net Banking | AF5: West
A6: ORD1005 | B6: 46077 | C6: C052 | D6: P110 | E6: 1 | F6: 9000 | G6: 0.1 | H6: Card | I6: North | J6: Karan | K6: =PRODUCT(E6,F6) -> 9000 | L6: =PRODUCT(K6,G6) -> 900 | M6: =K6-L6 -> 8100 | N6: =IF(M6>=50000,"High Value",IF(M6>=20000,"Medium Value","Low Value")) -> Low Value | O6: =IF(AND(E6>=5,G6>=15%),"High",IF(OR(E6>=3,G6>=10%),"Medium","Low")) -> Medium | P6: =RIGHT(C6,3) -> 052 | Q6: =RIGHT(D6,3) -> 110 | R6: =PROPER(TRIM(J6)) -> Karan | S6: =TRIM(PROPER(I6)) -> North | T6: =IFERROR(VLOOKUP(D6,Product_Reference!$A$1:$F$26,2,0),"Not Found!!") -> External SSD 1TB | U6: =IFERROR(VLOOKUP(D6,Product_Reference!$A$1:$F$26,3,0),"Not Found!!") -> Storage | V6: =IFERROR(VLOOKUP(D6,Product_Reference!$A$1:$F$26,4,0),"Not Found!!") -> DataDrive | W6: =IFERROR(VLOOKUP(D6,Product_Reference!$A$1:$F$26,5,0),"Not Found!!") -> PQR Ltd | X6: =IFERROR(VLOOKUP(D6,Product_Reference!$A$1:$F$26,6,0),"Not Found!!") -> 4.5 | AA6: 2. Calculate the total quantity of products sold. | AD6: Card | AF6: North | AH6: 13. Create a Net Sales column. Calculate the final sales value after deducting the discount.
A7: ORD1006 | B7: 46095 | C7: C039 | D7: P119 | E7: 3 | F7: 12500 | G7: 0.12 | H7: UPI | I7: East | J7: Sneha | K7: =PRODUCT(E7,F7) -> 37500 | L7: =PRODUCT(K7,G7) -> 4500 | M7: =K7-L7 -> 33000 | N7: =IF(M7>=50000,"High Value",IF(M7>=20000,"Medium Value","Low Value")) -> Medium Value | O7: =IF(AND(E7>=5,G7>=15%),"High",IF(OR(E7>=3,G7>=10%),"Medium","Low")) -> Medium | P7: =RIGHT(C7,3) -> 039 | Q7: =RIGHT(D7,3) -> 119 | R7: =PROPER(TRIM(J7)) -> Sneha | S7: =TRIM(PROPER(I7)) -> East | T7: =IFERROR(VLOOKUP(D7,Product_Reference!$A$1:$F$26,2,0),"Not Found!!") -> Office Chair | U7: =IFERROR(VLOOKUP(D7,Product_Reference!$A$1:$F$26,3,0),"Not Found!!") -> Furniture | V7: =IFERROR(VLOOKUP(D7,Product_Reference!$A$1:$F$26,4,0),"Not Found!!") -> ComfortPro | W7: =IFERROR(VLOOKUP(D7,Product_Reference!$A$1:$F$26,5,0),"Not Found!!") -> ABC Ltd | X7: =IFERROR(VLOOKUP(D7,Product_Reference!$A$1:$F$26,6,0),"Not Found!!") -> 4.2
A8: ORD1007 | B8: 46031 | C8: C026 | D8: P114 | E8: 1 | F8: 2500 | G8: 0.05 | H8: UPI | I8: South | J8: Sneha | K8: =PRODUCT(E8,F8) -> 2500 | L8: =PRODUCT(K8,G8) -> 125 | M8: =K8-L8 -> 2375 | N8: =IF(M8>=50000,"High Value",IF(M8>=20000,"Medium Value","Low Value")) -> Low Value | O8: =IF(AND(E8>=5,G8>=15%),"High",IF(OR(E8>=3,G8>=10%),"Medium","Low")) -> Low | P8: =RIGHT(C8,3) -> 026 | Q8: =RIGHT(D8,3) -> 114 | R8: =PROPER(TRIM(J8)) -> Sneha | S8: =TRIM(PROPER(I8)) -> South | T8: =IFERROR(VLOOKUP(D8,Product_Reference!$A$1:$F$26,2,0),"Not Found!!") -> Power Bank 20000mAh | U8: =IFERROR(VLOOKUP(D8,Product_Reference!$A$1:$F$26,3,0),"Not Found!!") -> Accessories | V8: =IFERROR(VLOOKUP(D8,Product_Reference!$A$1:$F$26,4,0),"Not Found!!") -> PowerPlus | W8: =IFERROR(VLOOKUP(D8,Product_Reference!$A$1:$F$26,5,0),"Not Found!!") -> PQR Ltd | X8: =IFERROR(VLOOKUP(D8,Product_Reference!$A$1:$F$26,6,0),"Not Found!!") -> 4.1 | AA8: Total Qty Sold | AB8: =SUM(E2:E151) -> 408 | AF8: Priya | AH8: 14. Create a Sales Category column. Classify each order as High Value, Medium Value, or Low Value based on Net Sales: High Value = ₹50,000 or more; Medium Value = ₹20,000 or more but below ₹50,000; Low Value = below ₹20,000.
A9: ORD1008 | B9: 46030 | C9: C047 | D9: P115 | E9: 3 | F9: 42000 | G9: 0.1 | H9: UPI | I9: East | J9: Sneha | K9: =PRODUCT(E9,F9) -> 126000 | L9: =PRODUCT(K9,G9) -> 12600 | M9: =K9-L9 -> 113400 | N9: =IF(M9>=50000,"High Value",IF(M9>=20000,"Medium Value","Low Value")) -> High Value | O9: =IF(AND(E9>=5,G9>=15%),"High",IF(OR(E9>=3,G9>=10%),"Medium","Low")) -> Medium | P9: =RIGHT(C9,3) -> 047 | Q9: =RIGHT(D9,3) -> 115 | R9: =PROPER(TRIM(J9)) -> Sneha | S9: =TRIM(PROPER(I9)) -> East | T9: =IFERROR(VLOOKUP(D9,Product_Reference!$A$1:$F$26,2,0),"Not Found!!") -> Smart TV 43 | U9: =IFERROR(VLOOKUP(D9,Product_Reference!$A$1:$F$26,3,0),"Not Found!!") -> Electronics | V9: =IFERROR(VLOOKUP(D9,Product_Reference!$A$1:$F$26,4,0),"Not Found!!") -> ViewMax | W9: =IFERROR(VLOOKUP(D9,Product_Reference!$A$1:$F$26,5,0),"Not Found!!") -> ABC Ltd | X9: =IFERROR(VLOOKUP(D9,Product_Reference!$A$1:$F$26,6,0),"Not Found!!") -> 4.6 | AF9: Amit
A10: ORD1009 | B10: 46024 | C10: C006 | D10: P118 | E10: 4 | F10: 650 | H10: UPI | I10: South | J10: Neha | K10: =PRODUCT(E10,F10) -> 2600 | L10: =PRODUCT(K10,G10) -> 2600 | M10: =K10-L10 -> 0 | N10: =IF(M10>=50000,"High Value",IF(M10>=20000,"Medium Value","Low Value")) -> Low Value | O10: =IF(AND(E10>=5,G10>=15%),"High",IF(OR(E10>=3,G10>=10%),"Medium","Low")) -> Medium | P10: =RIGHT(C10,3) -> 006 | Q10: =RIGHT(D10,3) -> 118 | R10: =PROPER(TRIM(J10)) -> Neha | S10: =TRIM(PROPER(I10)) -> South | T10: =IFERROR(VLOOKUP(D10,Product_Reference!$A$1:$F$26,2,0),"Not Found!!") -> Mechanical Pencil Set | U10: =IFERROR(VLOOKUP(D10,Product_Reference!$A$1:$F$26,3,0),"Not Found!!") -> Stationery | V10: =IFERROR(VLOOKUP(D10,Product_Reference!$A$1:$F$26,4,0),"Not Found!!") -> WriteWell | W10: =IFERROR(VLOOKUP(D10,Product_Reference!$A$1:$F$26,5,0),"Not Found!!") -> LMN Ltd | X10: =IFERROR(VLOOKUP(D10,Product_Reference!$A$1:$F$26,6,0),"Not Found!!") -> 4.3 | AA10: 3. Calculate the average quantity ordered per order. | AF10: Sneha | AH10: 15. Create an Order Priority column. Classify an order as High when Quantity is at least 5 AND Discount is at least 15%; Medium when Quantity is at least 3 OR Discount is at least 10%; otherwise classify it as Low.
A11: ORD1010 | B11: 46056 | C11: C010 | D11: P118 | E11: 6 | F11: 650 | G11: 0.1 | H11: Net Banking | I11: West | J11: Neha | K11: =PRODUCT(E11,F11) -> 3900 | L11: =PRODUCT(K11,G11) -> 390 | M11: =K11-L11 -> 3510 | N11: =IF(M11>=50000,"High Value",IF(M11>=20000,"Medium Value","Low Value")) -> Low Value | O11: =IF(AND(E11>=5,G11>=15%),"High",IF(OR(E11>=3,G11>=10%),"Medium","Low")) -> Medium | P11: =RIGHT(C11,3) -> 010 | Q11: =RIGHT(D11,3) -> 118 | R11: =PROPER(TRIM(J11)) -> Neha | S11: =TRIM(PROPER(I11)) -> West | T11: =IFERROR(VLOOKUP(D11,Product_Reference!$A$1:$F$26,2,0),"Not Found!!") -> Mechanical Pencil Set | U11: =IFERROR(VLOOKUP(D11,Product_Reference!$A$1:$F$26,3,0),"Not Found!!") -> Stationery | V11: =IFERROR(VLOOKUP(D11,Product_Reference!$A$1:$F$26,4,0),"Not Found!!") -> WriteWell | W11: =IFERROR(VLOOKUP(D11,Product_Reference!$A$1:$F$26,5,0),"Not Found!!") -> LMN Ltd | X11: =IFERROR(VLOOKUP(D11,Product_Reference!$A$1:$F$26,6,0),"Not Found!!") -> 4.3 | AF11: Rahul
A12: ORD1011 | B12: 46062 | C12: C021 | D12: P123 | E12: 5 | F12: 2800 | G12: 0.15 | H12: UPI | I12: West | J12: Karan | K12: =PRODUCT(E12,F12) -> 14000 | L12: =PRODUCT(K12,G12) -> 2100 | M12: =K12-L12 -> 11900 | N12: =IF(M12>=50000,"High Value",IF(M12>=20000,"Medium Value","Low Value")) -> Low Value | O12: =IF(AND(E12>=5,G12>=15%),"High",IF(OR(E12>=3,G12>=10%),"Medium","Low")) -> High | P12: =RIGHT(C12,3) -> 021 | Q12: =RIGHT(D12,3) -> 123 | R12: =PROPER(TRIM(J12)) -> Karan | S12: =TRIM(PROPER(I12)) -> West | T12: =IFERROR(VLOOKUP(D12,Product_Reference!$A$1:$F$26,2,0),"Not Found!!") -> Wi-Fi Range Extender | U12: =IFERROR(VLOOKUP(D12,Product_Reference!$A$1:$F$26,3,0),"Not Found!!") -> Networking | V12: =IFERROR(VLOOKUP(D12,Product_Reference!$A$1:$F$26,4,0),"Not Found!!") -> NetLink | W12: =IFERROR(VLOOKUP(D12,Product_Reference!$A$1:$F$26,5,0),"Not Found!!") -> XYZ Ltd | X12: =IFERROR(VLOOKUP(D12,Product_Reference!$A$1:$F$26,6,0),"Not Found!!") -> 4 | AA12: Average Qty Ordered | AB12: =AVERAGE(E2:E53) -> 2.6730769 | AF12: Karan | AH12: 16. Create a new column containing only the numeric portion of Customer_ID. For example, C001 should return 001.
A13: ORD1012 | B13: 46082 | C13: C060 | D13: P124 | E13: 6 | F13: 2500 | G13: 0 | H13: UPI | I13: East | J13: Karan | K13: =PRODUCT(E13,F13) -> 15000 | L13: =PRODUCT(K13,G13) -> 0 | M13: =K13-L13 -> 15000 | N13: =IF(M13>=50000,"High Value",IF(M13>=20000,"Medium Value","Low Value")) -> Low Value | O13: =IF(AND(E13>=5,G13>=15%),"High",IF(OR(E13>=3,G13>=10%),"Medium","Low")) -> Medium | P13: =RIGHT(C13,3) -> 060 | Q13: =RIGHT(D13,3) -> 124 | R13: =PROPER(TRIM(J13)) -> Karan | S13: =TRIM(PROPER(I13)) -> East | T13: =IFERROR(VLOOKUP(D13,Product_Reference!$A$1:$F$26,2,0),"Not Found!!") -> Tablet Keyboard | U13: =IFERROR(VLOOKUP(D13,Product_Reference!$A$1:$F$26,3,0),"Not Found!!") -> Accessories | V13: =IFERROR(VLOOKUP(D13,Product_Reference!$A$1:$F$26,4,0),"Not Found!!") -> KeyMaster | W13: =IFERROR(VLOOKUP(D13,Product_Reference!$A$1:$F$26,5,0),"Not Found!!") -> PQR Ltd | X13: =IFERROR(VLOOKUP(D13,Product_Reference!$A$1:$F$26,6,0),"Not Found!!") -> 3.8 | AF13: Neha
A14: ORD1013 | B14: 46031 | C14: C024 | D14: P101 | E14: 5 | F14: 45000 | G14: 0.18 | H14: UPI | I14: east | J14: Amit | K14: =PRODUCT(E14,F14) -> 225000 | L14: =PRODUCT(K14,G14) -> 40500 | M14: =K14-L14 -> 184500 | N14: =IF(M14>=50000,"High Value",IF(M14>=20000,"Medium Value","Low Value")) -> High Value | O14: =IF(AND(E14>=5,G14>=15%),"High",IF(OR(E14>=3,G14>=10%),"Medium","Low")) -> High | P14: =RIGHT(C14,3) -> 024 | Q14: =RIGHT(D14,3) -> 101 | R14: =PROPER(TRIM(J14)) -> Amit | S14: =TRIM(PROPER(I14)) -> East | T14: =IFERROR(VLOOKUP(D14,Product_Reference!$A$1:$F$26,2,0),"Not Found!!") -> Laptop Pro 14 | U14: =IFERROR(VLOOKUP(D14,Product_Reference!$A$1:$F$26,3,0),"Not Found!!") -> Electronics | V14: =IFERROR(VLOOKUP(D14,Product_Reference!$A$1:$F$26,4,0),"Not Found!!") -> TechPro | W14: =IFERROR(VLOOKUP(D14,Product_Reference!$A$1:$F$26,5,0),"Not Found!!") -> ABC Ltd | X14: =IFERROR(VLOOKUP(D14,Product_Reference!$A$1:$F$26,6,0),"Not Found!!") -> 4.5 | AA14: 4. Find the number of orders made using each payment mode: UPI, Card, Cash, and Net Banking.
A15: ORD1014 | B15: 46057 | C15: C035 | D15: P119 | E15: 1 | F15: 12500 | G15: 0.2 | H15: Cash | I15: East | J15: Priya | K15: =PRODUCT(E15,F15) -> 12500 | L15: =PRODUCT(K15,G15) -> 2500 | M15: =K15-L15 -> 10000 | N15: =IF(M15>=50000,"High Value",IF(M15>=20000,"Medium Value","Low Value")) -> Low Value | O15: =IF(AND(E15>=5,G15>=15%),"High",IF(OR(E15>=3,G15>=10%),"Medium","Low")) -> Medium | P15: =RIGHT(C15,3) -> 035 | Q15: =RIGHT(D15,3) -> 119 | R15: =PROPER(TRIM(J15)) -> Priya | S15: =TRIM(PROPER(I15)) -> East | T15: =IFERROR(VLOOKUP(D15,Product_Reference!$A$1:$F$26,2,0),"Not Found!!") -> Office Chair | U15: =IFERROR(VLOOKUP(D15,Product_Reference!$A$1:$F$26,3,0),"Not Found!!") -> Furniture | V15: =IFERROR(VLOOKUP(D15,Product_Reference!$A$1:$F$26,4,0),"Not Found!!") -> ComfortPro | W15: =IFERROR(VLOOKUP(D15,Product_Reference!$A$1:$F$26,5,0),"Not Found!!") -> ABC Ltd | X15: =IFERROR(VLOOKUP(D15,Product_Reference!$A$1:$F$26,6,0),"Not Found!!") -> 4.2 | AH15: 17. Create a new column containing only the numeric portion of Product_ID. For example, P101 should return 101.
A16: ORD1015 | B16: 46050 | C16: C007 | D16: P107 | E16: 6 | F16: 2200 | G16: 0 | H16: Net Banking | I16: South | J16: Priya | K16: =PRODUCT(E16,F16) -> 13200 | L16: =PRODUCT(K16,G16) -> 0 | M16: =K16-L16 -> 13200 | N16: =IF(M16>=50000,"High Value",IF(M16>=20000,"Medium Value","Low Value")) -> Low Value | O16: =IF(AND(E16>=5,G16>=15%),"High",IF(OR(E16>=3,G16>=10%),"Medium","Low")) -> Medium | P16: =RIGHT(C16,3) -> 007 | Q16: =RIGHT(D16,3) -> 107 | R16: =PROPER(TRIM(J16)) -> Priya | S16: =TRIM(PROPER(I16)) -> South | T16: =IFERROR(VLOOKUP(D16,Product_Reference!$A$1:$F$26,2,0),"Not Found!!") -> USB-C Hub | U16: =IFERROR(VLOOKUP(D16,Product_Reference!$A$1:$F$26,3,0),"Not Found!!") -> Accessories | V16: =IFERROR(VLOOKUP(D16,Product_Reference!$A$1:$F$26,4,0),"Not Found!!") -> ConnectPro | W16: =IFERROR(VLOOKUP(D16,Product_Reference!$A$1:$F$26,5,0),"Not Found!!") -> PQR Ltd | X16: =IFERROR(VLOOKUP(D16,Product_Reference!$A$1:$F$26,6,0),"Not Found!!") -> 4.3 | AA16: Payment_Mode | AB16: No.of Orders
A17: ORD1016 | B17: 46084 | C17: C024 | D17: P101 | E17: 3 | F17: 45000 | G17: 0.18 | H17: Card | I17: South | J17: Neha | K17: =PRODUCT(E17,F17) -> 135000 | L17: =PRODUCT(K17,G17) -> 24300 | M17: =K17-L17 -> 110700 | N17: =IF(M17>=50000,"High Value",IF(M17>=20000,"Medium Value","Low Value")) -> High Value | O17: =IF(AND(E17>=5,G17>=15%),"High",IF(OR(E17>=3,G17>=10%),"Medium","Low")) -> Medium | P17: =RIGHT(C17,3) -> 024 | Q17: =RIGHT(D17,3) -> 101 | R17: =PROPER(TRIM(J17)) -> Neha | S17: =TRIM(PROPER(I17)) -> South | T17: =IFERROR(VLOOKUP(D17,Product_Reference!$A$1:$F$26,2,0),"Not Found!!") -> Laptop Pro 14 | U17: =IFERROR(VLOOKUP(D17,Product_Reference!$A$1:$F$26,3,0),"Not Found!!") -> Electronics | V17: =IFERROR(VLOOKUP(D17,Product_Reference!$A$1:$F$26,4,0),"Not Found!!") -> TechPro | W17: =IFERROR(VLOOKUP(D17,Product_Reference!$A$1:$F$26,5,0),"Not Found!!") -> ABC Ltd | X17: =IFERROR(VLOOKUP(D17,Product_Reference!$A$1:$F$26,6,0),"Not Found!!") -> 4.5 | AA17: Cash | AB17: =COUNTIF(H2:H92,AA17) -> 6 | AH17: 18. Create a cleaned Salesperson column in Proper Case.
A18: ORD1017 | B18: 46069 | C18: C014 | D18: P103 | E18: 1 | F18: 65000 | G18: 0.08 | H18: Net Banking | I18: East | J18: Priya | K18: =PRODUCT(E18,F18) -> 65000 | L18: =PRODUCT(K18,G18) -> 5200 | M18: =K18-L18 -> 59800 | N18: =IF(M18>=50000,"High Value",IF(M18>=20000,"Medium Value","Low Value")) -> High Value | O18: =IF(AND(E18>=5,G18>=15%),"High",IF(OR(E18>=3,G18>=10%),"Medium","Low")) -> Low | P18: =RIGHT(C18,3) -> 014 | Q18: =RIGHT(D18,3) -> 103 | R18: =PROPER(TRIM(J18)) -> Priya | S18: =TRIM(PROPER(I18)) -> East | T18: =IFERROR(VLOOKUP(D18,Product_Reference!$A$1:$F$26,2,0),"Not Found!!") -> Smartphone X | U18: =IFERROR(VLOOKUP(D18,Product_Reference!$A$1:$F$26,3,0),"Not Found!!") -> Electronics | V18: =IFERROR(VLOOKUP(D18,Product_Reference!$A$1:$F$26,4,0),"Not Found!!") -> MobileMax | W18: =IFERROR(VLOOKUP(D18,Product_Reference!$A$1:$F$26,5,0),"Not Found!!") -> ABC Ltd | X18: =IFERROR(VLOOKUP(D18,Product_Reference!$A$1:$F$26,6,0),"Not Found!!") -> 4.6
A19: ORD1018 | B19: 46031 | C19: C015 | D19: P123 | E19: 3 | F19: 2800 | G19: 0.08 | H19: Card | I19: West | J19: Sneha | K19: =PRODUCT(E19,F19) -> 8400 | L19: =PRODUCT(K19,G19) -> 672 | M19: =K19-L19 -> 7728 | N19: =IF(M19>=50000,"High Value",IF(M19>=20000,"Medium Value","Low Value")) -> Low Value | O19: =IF(AND(E19>=5,G19>=15%),"High",IF(OR(E19>=3,G19>=10%),"Medium","Low")) -> Medium | P19: =RIGHT(C19,3) -> 015 | Q19: =RIGHT(D19,3) -> 123 | R19: =PROPER(TRIM(J19)) -> Sneha | S19: =TRIM(PROPER(I19)) -> West | T19: =IFERROR(VLOOKUP(D19,Product_Reference!$A$1:$F$26,2,0),"Not Found!!") -> Wi-Fi Range Extender | U19: =IFERROR(VLOOKUP(D19,Product_Reference!$A$1:$F$26,3,0),"Not Found!!") -> Networking | V19: =IFERROR(VLOOKUP(D19,Product_Reference!$A$1:$F$26,4,0),"Not Found!!") -> NetLink | W19: =IFERROR(VLOOKUP(D19,Product_Reference!$A$1:$F$26,5,0),"Not Found!!") -> XYZ Ltd | X19: =IFERROR(VLOOKUP(D19,Product_Reference!$A$1:$F$26,6,0),"Not Found!!") -> 4 | AA19: 5. Find the number of orders received from each region: East, West, North, and South. | AH19: 19. Create a cleaned Region column by removing unnecessary leading and trailing spaces.
A20: ORD1019 | B20: 46074 | C20: C032 | D20: P113 | E20: 1 | F20: 5500 | G20: 0.18 | H20: Card | I20: East | J20: Karan | K20: =PRODUCT(E20,F20) -> 5500 | L20: =PRODUCT(K20,G20) -> 990 | M20: =K20-L20 -> 4510 | N20: =IF(M20>=50000,"High Value",IF(M20>=20000,"Medium Value","Low Value")) -> Low Value | O20: =IF(AND(E20>=5,G20>=15%),"High",IF(OR(E20>=3,G20>=10%),"Medium","Low")) -> Medium | P20: =RIGHT(C20,3) -> 032 | Q20: =RIGHT(D20,3) -> 113 | R20: =PROPER(TRIM(J20)) -> Karan | S20: =TRIM(PROPER(I20)) -> East | T20: =IFERROR(VLOOKUP(D20,Product_Reference!$A$1:$F$26,2,0),"Not Found!!") -> Wireless Earbuds | U20: =IFERROR(VLOOKUP(D20,Product_Reference!$A$1:$F$26,3,0),"Not Found!!") -> Audio | V20: =IFERROR(VLOOKUP(D20,Product_Reference!$A$1:$F$26,4,0),"Not Found!!") -> SoundMax | W20: =IFERROR(VLOOKUP(D20,Product_Reference!$A$1:$F$26,5,0),"Not Found!!") -> LMN Ltd | X20: =IFERROR(VLOOKUP(D20,Product_Reference!$A$1:$F$26,6,0),"Not Found!!") -> 4.4
A21: ORD1020 | B21: 46054 | C21: C007 | D21: P115 | E21: 2 | F21: 42000 | G21: 0.12 | H21: UPI | I21: West | J21: Sneha | K21: =PRODUCT(E21,F21) -> 84000 | L21: =PRODUCT(K21,G21) -> 10080 | M21: =K21-L21 -> 73920 | N21: =IF(M21>=50000,"High Value",IF(M21>=20000,"Medium Value","Low Value")) -> High Value | O21: =IF(AND(E21>=5,G21>=15%),"High",IF(OR(E21>=3,G21>=10%),"Medium","Low")) -> Medium | P21: =RIGHT(C21,3) -> 007 | Q21: =RIGHT(D21,3) -> 115 | R21: =PROPER(TRIM(J21)) -> Sneha | S21: =TRIM(PROPER(I21)) -> West | T21: =IFERROR(VLOOKUP(D21,Product_Reference!$A$1:$F$26,2,0),"Not Found!!") -> Smart TV 43 | U21: =IFERROR(VLOOKUP(D21,Product_Reference!$A$1:$F$26,3,0),"Not Found!!") -> Electronics | V21: =IFERROR(VLOOKUP(D21,Product_Reference!$A$1:$F$26,4,0),"Not Found!!") -> ViewMax | W21: =IFERROR(VLOOKUP(D21,Product_Reference!$A$1:$F$26,5,0),"Not Found!!") -> ABC Ltd | X21: =IFERROR(VLOOKUP(D21,Product_Reference!$A$1:$F$26,6,0),"Not Found!!") -> 4.6 | AA21: Region | AB21: No. of Orders | AH21: 20. Using VLOOKUP, retrieve the Product Name for every order.
A22: ORD1021 | B22: 46084 | C22: C057 | D22: P102 | E22: 6 | F22: 1200 | G22: 0.12 | H22: UPI | I22: South | J22: Sneha | K22: =PRODUCT(E22,F22) -> 7200 | L22: =PRODUCT(K22,G22) -> 864 | M22: =K22-L22 -> 6336 | N22: =IF(M22>=50000,"High Value",IF(M22>=20000,"Medium Value","Low Value")) -> Low Value | O22: =IF(AND(E22>=5,G22>=15%),"High",IF(OR(E22>=3,G22>=10%),"Medium","Low")) -> Medium | P22: =RIGHT(C22,3) -> 057 | Q22: =RIGHT(D22,3) -> 102 | R22: =PROPER(TRIM(J22)) -> Sneha | S22: =TRIM(PROPER(I22)) -> South | T22: =IFERROR(VLOOKUP(D22,Product_Reference!$A$1:$F$26,2,0),"Not Found!!") -> Wireless Mouse | U22: =IFERROR(VLOOKUP(D22,Product_Reference!$A$1:$F$26,3,0),"Not Found!!") -> Accessories | V22: =IFERROR(VLOOKUP(D22,Product_Reference!$A$1:$F$26,4,0),"Not Found!!") -> ClickTech | W22: =IFERROR(VLOOKUP(D22,Product_Reference!$A$1:$F$26,5,0),"Not Found!!") -> XYZ Ltd | X22: =IFERROR(VLOOKUP(D22,Product_Reference!$A$1:$F$26,6,0),"Not Found!!") -> 4.2 | AA22: East | AB22: =COUNTIF(S2:S151,AA22) -> 33
A23: ORD1022 | B23: 46084 | C23: C011 | D23: P112 | E23: 2 | F23: 3200 | G23: 0.15 | H23: UPI | I23: North | J23: Sneha | K23: =PRODUCT(E23,F23) -> 6400 | L23: =PRODUCT(K23,G23) -> 960 | M23: =K23-L23 -> 5440 | N23: =IF(M23>=50000,"High Value",IF(M23>=20000,"Medium Value","Low Value")) -> Low Value | O23: =IF(AND(E23>=5,G23>=15%),"High",IF(OR(E23>=3,G23>=10%),"Medium","Low")) -> Medium | P23: =RIGHT(C23,3) -> 011 | Q23: =RIGHT(D23,3) -> 112 | R23: =PROPER(TRIM(J23)) -> Sneha | S23: =TRIM(PROPER(I23)) -> North | T23: =IFERROR(VLOOKUP(D23,Product_Reference!$A$1:$F$26,2,0),"Not Found!!") -> Webcam HD | U23: =IFERROR(VLOOKUP(D23,Product_Reference!$A$1:$F$26,3,0),"Not Found!!") -> Accessories | V23: =IFERROR(VLOOKUP(D23,Product_Reference!$A$1:$F$26,4,0),"Not Found!!") -> VisionTech | W23: =IFERROR(VLOOKUP(D23,Product_Reference!$A$1:$F$26,5,0),"Not Found!!") -> ABC Ltd | X23: =IFERROR(VLOOKUP(D23,Product_Reference!$A$1:$F$26,6,0),"Not Found!!") -> 3.8 | AH23: 21. Using VLOOKUP, retrieve the Category for every order.
A24: ORD1023 | B24: 46023 | C24: C057 | D24: P125 | E24: 3 | F24: 16000 | G24: 0.15 | H24: Card | J24: Sneha | K24: =PRODUCT(E24,F24) -> 48000 | L24: =PRODUCT(K24,G24) -> 7200 | M24: =K24-L24 -> 40800 | N24: =IF(M24>=50000,"High Value",IF(M24>=20000,"Medium Value","Low Value")) -> Medium Value | O24: =IF(AND(E24>=5,G24>=15%),"High",IF(OR(E24>=3,G24>=10%),"Medium","Low")) -> Medium | P24: =RIGHT(C24,3) -> 057 | Q24: =RIGHT(D24,3) -> 125 | R24: =PROPER(TRIM(J24)) -> Sneha | S24: =TRIM(PROPER(I24)) | T24: =IFERROR(VLOOKUP(D24,Product_Reference!$A$1:$F$26,2,0),"Not Found!!") -> Laser Printer | U24: =IFERROR(VLOOKUP(D24,Product_Reference!$A$1:$F$26,3,0),"Not Found!!") -> Office Equipment | V24: =IFERROR(VLOOKUP(D24,Product_Reference!$A$1:$F$26,4,0),"Not Found!!") -> PrintPro | W24: =IFERROR(VLOOKUP(D24,Product_Reference!$A$1:$F$26,5,0),"Not Found!!") -> ABC Ltd | X24: =IFERROR(VLOOKUP(D24,Product_Reference!$A$1:$F$26,6,0),"Not Found!!") -> 4.2 | AA24: 6. Find the number of orders where Quantity is greater than or equal to 3.
A25: ORD1024 | B25: 46092 | C25: C008 | D25: P113 | E25: 5 | F25: 5500 | G25: 0.08 | H25: Card | I25: West | J25: Karan | K25: =PRODUCT(E25,F25) -> 27500 | L25: =PRODUCT(K25,G25) -> 2200 | M25: =K25-L25 -> 25300 | N25: =IF(M25>=50000,"High Value",IF(M25>=20000,"Medium Value","Low Value")) -> Medium Value | O25: =IF(AND(E25>=5,G25>=15%),"High",IF(OR(E25>=3,G25>=10%),"Medium","Low")) -> Medium | P25: =RIGHT(C25,3) -> 008 | Q25: =RIGHT(D25,3) -> 113 | R25: =PROPER(TRIM(J25)) -> Karan | S25: =TRIM(PROPER(I25)) -> West | T25: =IFERROR(VLOOKUP(D25,Product_Reference!$A$1:$F$26,2,0),"Not Found!!") -> Wireless Earbuds | U25: =IFERROR(VLOOKUP(D25,Product_Reference!$A$1:$F$26,3,0),"Not Found!!") -> Audio | V25: =IFERROR(VLOOKUP(D25,Product_Reference!$A$1:$F$26,4,0),"Not Found!!") -> SoundMax | W25: =IFERROR(VLOOKUP(D25,Product_Reference!$A$1:$F$26,5,0),"Not Found!!") -> LMN Ltd | X25: =IFERROR(VLOOKUP(D25,Product_Reference!$A$1:$F$26,6,0),"Not Found!!") -> 4.4 | AH25: 22. Using VLOOKUP, retrieve the Brand for every order.
A26: ORD1025 | B26: 46066 | C26: C024 | D26: P101 | E26: 1 | F26: 45000 | G26: 0.05 | H26: Net Banking | I26: West | J26: Rahul | K26: =PRODUCT(E26,F26) -> 45000 | L26: =PRODUCT(K26,G26) -> 2250 | M26: =K26-L26 -> 42750 | N26: =IF(M26>=50000,"High Value",IF(M26>=20000,"Medium Value","Low Value")) -> Medium Value | O26: =IF(AND(E26>=5,G26>=15%),"High",IF(OR(E26>=3,G26>=10%),"Medium","Low")) -> Low | P26: =RIGHT(C26,3) -> 024 | Q26: =RIGHT(D26,3) -> 101 | R26: =PROPER(TRIM(J26)) -> Rahul | S26: =TRIM(PROPER(I26)) -> West | T26: =IFERROR(VLOOKUP(D26,Product_Reference!$A$1:$F$26,2,0),"Not Found!!") -> Laptop Pro 14 | U26: =IFERROR(VLOOKUP(D26,Product_Reference!$A$1:$F$26,3,0),"Not Found!!") -> Electronics | V26: =IFERROR(VLOOKUP(D26,Product_Reference!$A$1:$F$26,4,0),"Not Found!!") -> TechPro | W26: =IFERROR(VLOOKUP(D26,Product_Reference!$A$1:$F$26,5,0),"Not Found!!") -> ABC Ltd | X26: =IFERROR(VLOOKUP(D26,Product_Reference!$A$1:$F$26,6,0),"Not Found!!") -> 4.5 | AA26: No. of Orders gte 3 | AB26: =COUNTIF(E2:E151,">=3") -> 64
A27: ORD1026 | B27: 46080 | C27: C052 | D27: P120 | E27: 1 | F27: 2200 | G27: 0.15 | H27: UPI | I27: North | J27: Priya | K27: =PRODUCT(E27,F27) -> 2200 | L27: =PRODUCT(K27,G27) -> 330 | M27: =K27-L27 -> 1870 | N27: =IF(M27>=50000,"High Value",IF(M27>=20000,"Medium Value","Low Value")) -> Low Value | O27: =IF(AND(E27>=5,G27>=15%),"High",IF(OR(E27>=3,G27>=10%),"Medium","Low")) -> Medium | P27: =RIGHT(C27,3) -> 052 | Q27: =RIGHT(D27,3) -> 120 | R27: =PROPER(TRIM(J27)) -> Priya | S27: =TRIM(PROPER(I27)) -> North | T27: =IFERROR(VLOOKUP(D27,Product_Reference!$A$1:$F$26,2,0),"Not Found!!") -> Desk Lamp | U27: =IFERROR(VLOOKUP(D27,Product_Reference!$A$1:$F$26,3,0),"Not Found!!") -> Furniture | V27: =IFERROR(VLOOKUP(D27,Product_Reference!$A$1:$F$26,4,0),"Not Found!!") -> BrightHome | W27: =IFERROR(VLOOKUP(D27,Product_Reference!$A$1:$F$26,5,0),"Not Found!!") -> XYZ Ltd | X27: =IFERROR(VLOOKUP(D27,Product_Reference!$A$1:$F$26,6,0),"Not Found!!") -> 3.9 | AH27: 23. Using VLOOKUP, retrieve the Supplier for every order.
A28: ORD1027 | B28: 46078 | C28: C017 | D28: P103 | E28: 1 | F28: 65000 | G28: 0.12 | H28: UPI | I28: West | J28: Priya | K28: =PRODUCT(E28,F28) -> 65000 | L28: =PRODUCT(K28,G28) -> 7800 | M28: =K28-L28 -> 57200 | N28: =IF(M28>=50000,"High Value",IF(M28>=20000,"Medium Value","Low Value")) -> High Value | O28: =IF(AND(E28>=5,G28>=15%),"High",IF(OR(E28>=3,G28>=10%),"Medium","Low")) -> Medium | P28: =RIGHT(C28,3) -> 017 | Q28: =RIGHT(D28,3) -> 103 | R28: =PROPER(TRIM(J28)) -> Priya | S28: =TRIM(PROPER(I28)) -> West | T28: =IFERROR(VLOOKUP(D28,Product_Reference!$A$1:$F$26,2,0),"Not Found!!") -> Smartphone X | U28: =IFERROR(VLOOKUP(D28,Product_Reference!$A$1:$F$26,3,0),"Not Found!!") -> Electronics | V28: =IFERROR(VLOOKUP(D28,Product_Reference!$A$1:$F$26,4,0),"Not Found!!") -> MobileMax | W28: =IFERROR(VLOOKUP(D28,Product_Reference!$A$1:$F$26,5,0),"Not Found!!") -> ABC Ltd | X28: =IFERROR(VLOOKUP(D28,Product_Reference!$A$1:$F$26,6,0),"Not Found!!") -> 4.6 | AA28: 7. Find the number of orders where Discount is greater than 10%.
A29: ORD1028 | B29: 46023 | C29: C019 | D29: P122 | E29: 3 | F29: 5500 | G29: 0.12 | H29: Card | I29: East | J29: Sneha | K29: =PRODUCT(E29,F29) -> 16500 | L29: =PRODUCT(K29,G29) -> 1980 | M29: =K29-L29 -> 14520 | N29: =IF(M29>=50000,"High Value",IF(M29>=20000,"Medium Value","Low Value")) -> Low Value | O29: =IF(AND(E29>=5,G29>=15%),"High",IF(OR(E29>=3,G29>=10%),"Medium","Low")) -> Medium | P29: =RIGHT(C29,3) -> 019 | Q29: =RIGHT(D29,3) -> 122 | R29: =PROPER(TRIM(J29)) -> Sneha | S29: =TRIM(PROPER(I29)) -> East | T29: =IFERROR(VLOOKUP(D29,Product_Reference!$A$1:$F$26,2,0),"Not Found!!") -> Router AX1800 | U29: =IFERROR(VLOOKUP(D29,Product_Reference!$A$1:$F$26,3,0),"Not Found!!") -> Networking | V29: =IFERROR(VLOOKUP(D29,Product_Reference!$A$1:$F$26,4,0),"Not Found!!") -> NetLink | W29: =IFERROR(VLOOKUP(D29,Product_Reference!$A$1:$F$26,5,0),"Not Found!!") -> ABC Ltd | X29: =IFERROR(VLOOKUP(D29,Product_Reference!$A$1:$F$26,6,0),"Not Found!!") -> 4.5 | AH29: 24. Using VLOOKUP, retrieve the Product Rating for every order.
A30: ORD1029 | B30: 46077 | C30: C011 | D30: P106 | E30: 3 | F30: 4500 | G30: 0.1 | H30: UPI | I30: WEST | J30: Neha | K30: =PRODUCT(E30,F30) -> 13500 | L30: =PRODUCT(K30,G30) -> 1350 | M30: =K30-L30 -> 12150 | N30: =IF(M30>=50000,"High Value",IF(M30>=20000,"Medium Value","Low Value")) -> Low Value | O30: =IF(AND(E30>=5,G30>=15%),"High",IF(OR(E30>=3,G30>=10%),"Medium","Low")) -> Medium | P30: =RIGHT(C30,3) -> 011 | Q30: =RIGHT(D30,3) -> 106 | R30: =PROPER(TRIM(J30)) -> Neha | S30: =TRIM(PROPER(I30)) -> West | T30: =IFERROR(VLOOKUP(D30,Product_Reference!$A$1:$F$26,2,0),"Not Found!!") -> Bluetooth Speaker | U30: =IFERROR(VLOOKUP(D30,Product_Reference!$A$1:$F$26,3,0),"Not Found!!") -> Audio | V30: =IFERROR(VLOOKUP(D30,Product_Reference!$A$1:$F$26,4,0),"Not Found!!") -> SoundMax | W30: =IFERROR(VLOOKUP(D30,Product_Reference!$A$1:$F$26,5,0),"Not Found!!") -> LMN Ltd | X30: =IFERROR(VLOOKUP(D30,Product_Reference!$A$1:$F$26,6,0),"Not Found!!") -> 3.9 | AA30: No. orders disc > 10% | AB30: =COUNTIF(G2:G151,">10%") -> 81
A31: ORD1030 | B31: 46092 | C31: C022 | D31: P124 | E31: 2 | F31: 2500 | G31: 0.1 | H31: Card | I31: South | J31: Rahul | K31: =PRODUCT(E31,F31) -> 5000 | L31: =PRODUCT(K31,G31) -> 500 | M31: =K31-L31 -> 4500 | N31: =IF(M31>=50000,"High Value",IF(M31>=20000,"Medium Value","Low Value")) -> Low Value | O31: =IF(AND(E31>=5,G31>=15%),"High",IF(OR(E31>=3,G31>=10%),"Medium","Low")) -> Medium | P31: =RIGHT(C31,3) -> 022 | Q31: =RIGHT(D31,3) -> 124 | R31: =PROPER(TRIM(J31)) -> Rahul | S31: =TRIM(PROPER(I31)) -> South | T31: =IFERROR(VLOOKUP(D31,Product_Reference!$A$1:$F$26,2,0),"Not Found!!") -> Tablet Keyboard | U31: =IFERROR(VLOOKUP(D31,Product_Reference!$A$1:$F$26,3,0),"Not Found!!") -> Accessories | V31: =IFERROR(VLOOKUP(D31,Product_Reference!$A$1:$F$26,4,0),"Not Found!!") -> KeyMaster | W31: =IFERROR(VLOOKUP(D31,Product_Reference!$A$1:$F$26,5,0),"Not Found!!") -> PQR Ltd | X31: =IFERROR(VLOOKUP(D31,Product_Reference!$A$1:$F$26,6,0),"Not Found!!") -> 3.8 | AH31: 25. Retrieve Product Name, Category, Brand, Supplier, and Product Rating using the multi-value VLOOKUP technique covered in class.
A32: ORD1031 | B32: 46025 | C32: C020 | D32: P109 | E32: 3 | F32: 8500 | G32: 0.2 | H32: UPI | I32: South | J32: Amit | K32: =PRODUCT(E32,F32) -> 25500 | L32: =PRODUCT(K32,G32) -> 5100 | M32: =K32-L32 -> 20400 | N32: =IF(M32>=50000,"High Value",IF(M32>=20000,"Medium Value","Low Value")) -> Medium Value | O32: =IF(AND(E32>=5,G32>=15%),"High",IF(OR(E32>=3,G32>=10%),"Medium","Low")) -> Medium | P32: =RIGHT(C32,3) -> 020 | Q32: =RIGHT(D32,3) -> 109 | R32: =PROPER(TRIM(J32)) -> Amit | S32: =TRIM(PROPER(I32)) -> South | T32: =IFERROR(VLOOKUP(D32,Product_Reference!$A$1:$F$26,2,0),"Not Found!!") -> Noise Cancelling Headphones | U32: =IFERROR(VLOOKUP(D32,Product_Reference!$A$1:$F$26,3,0),"Not Found!!") -> Audio | V32: =IFERROR(VLOOKUP(D32,Product_Reference!$A$1:$F$26,4,0),"Not Found!!") -> SoundMax | W32: =IFERROR(VLOOKUP(D32,Product_Reference!$A$1:$F$26,5,0),"Not Found!!") -> LMN Ltd | X32: =IFERROR(VLOOKUP(D32,Product_Reference!$A$1:$F$26,6,0),"Not Found!!") -> 4.7 | AA32: 8. Find the number of orders where Payment Mode is UPI and Region is East.
A33: ORD1032 | B33: 46093 | C33: C052 | D33: P103 | E33: 1 | F33: 65000 | G33: 0.1 | H33: Net Banking | I33: South | J33: Priya | K33: =PRODUCT(E33,F33) -> 65000 | L33: =PRODUCT(K33,G33) -> 6500 | M33: =K33-L33 -> 58500 | N33: =IF(M33>=50000,"High Value",IF(M33>=20000,"Medium Value","Low Value")) -> High Value | O33: =IF(AND(E33>=5,G33>=15%),"High",IF(OR(E33>=3,G33>=10%),"Medium","Low")) -> Medium | P33: =RIGHT(C33,3) -> 052 | Q33: =RIGHT(D33,3) -> 103 | R33: =PROPER(TRIM(J33)) -> Priya | S33: =TRIM(PROPER(I33)) -> South | T33: =IFERROR(VLOOKUP(D33,Product_Reference!$A$1:$F$26,2,0),"Not Found!!") -> Smartphone X | U33: =IFERROR(VLOOKUP(D33,Product_Reference!$A$1:$F$26,3,0),"Not Found!!") -> Electronics | V33: =IFERROR(VLOOKUP(D33,Product_Reference!$A$1:$F$26,4,0),"Not Found!!") -> MobileMax | W33: =IFERROR(VLOOKUP(D33,Product_Reference!$A$1:$F$26,5,0),"Not Found!!") -> ABC Ltd | X33: =IFERROR(VLOOKUP(D33,Product_Reference!$A$1:$F$26,6,0),"Not Found!!") -> 4.6 | AH33: Product_ID | AI33: Product Name | AJ33: Category | AK33: Brand | AL33: Supplier | AM33: Product Rating | AO33: P107
A34: ORD1033 | B34: 46079 | C34: C025 | D34: P108 | E34: 1 | F34: 7000 | G34: 0.08 | H34: UPI | I34: North | J34: Neha | K34: =PRODUCT(E34,F34) -> 7000 | L34: =PRODUCT(K34,G34) -> 560 | M34: =K34-L34 -> 6440 | N34: =IF(M34>=50000,"High Value",IF(M34>=20000,"Medium Value","Low Value")) -> Low Value | O34: =IF(AND(E34>=5,G34>=15%),"High",IF(OR(E34>=3,G34>=10%),"Medium","Low")) -> Low | P34: =RIGHT(C34,3) -> 025 | Q34: =RIGHT(D34,3) -> 108 | R34: =PROPER(TRIM(J34)) -> Neha | S34: =TRIM(PROPER(I34)) -> North | T34: =IFERROR(VLOOKUP(D34,Product_Reference!$A$1:$F$26,2,0),"Not Found!!") -> Smart Watch | U34: =IFERROR(VLOOKUP(D34,Product_Reference!$A$1:$F$26,3,0),"Not Found!!") -> Wearables | V34: =IFERROR(VLOOKUP(D34,Product_Reference!$A$1:$F$26,4,0),"Not Found!!") -> FitTech | W34: =IFERROR(VLOOKUP(D34,Product_Reference!$A$1:$F$26,5,0),"Not Found!!") -> ABC Ltd | X34: =IFERROR(VLOOKUP(D34,Product_Reference!$A$1:$F$26,6,0),"Not Found!!") -> 4 | AA34: Payment_Mode | AB34: Region | AC34: No. of Orders | AH34: P107 | AI34: {=IFERROR(VLOOKUP(AH34,Product_Reference!$A$1:$F$26,{2,3,4,5,6},0),"Not Found!!")} -> USB-C Hub | AJ34: Accessories | AK34: ConnectPro | AL34: PQR Ltd | AM34: 4.3 | AO34: P119
A35: ORD1034 | B35: 46038 | C35: C026 | D35: P110 | E35: 1 | F35: 9000 | G35: 0.18 | H35: Net Banking | I35: South | J35: Sneha | K35: =PRODUCT(E35,F35) -> 9000 | L35: =PRODUCT(K35,G35) -> 1620 | M35: =K35-L35 -> 7380 | N35: =IF(M35>=50000,"High Value",IF(M35>=20000,"Medium Value","Low Value")) -> Low Value | O35: =IF(AND(E35>=5,G35>=15%),"High",IF(OR(E35>=3,G35>=10%),"Medium","Low")) -> Medium | P35: =RIGHT(C35,3) -> 026 | Q35: =RIGHT(D35,3) -> 110 | R35: =PROPER(TRIM(J35)) -> Sneha | S35: =TRIM(PROPER(I35)) -> South | T35: =IFERROR(VLOOKUP(D35,Product_Reference!$A$1:$F$26,2,0),"Not Found!!") -> External SSD 1TB | U35: =IFERROR(VLOOKUP(D35,Product_Reference!$A$1:$F$26,3,0),"Not Found!!") -> Storage | V35: =IFERROR(VLOOKUP(D35,Product_Reference!$A$1:$F$26,4,0),"Not Found!!") -> DataDrive | W35: =IFERROR(VLOOKUP(D35,Product_Reference!$A$1:$F$26,5,0),"Not Found!!") -> PQR Ltd | X35: =IFERROR(VLOOKUP(D35,Product_Reference!$A$1:$F$26,6,0),"Not Found!!") -> 4.5 | AA35: UPI | AB35: East | AC35: =COUNTIFS(H2:H151,AA35,S2:S151,AB35) -> 14 | AO35: P122
A36: ORD1035 | B36: 46070 | C36: C012 | D36: P117 | E36: 1 | F36: 1800 | G36: 0 | H36: Card | I36: South | J36: Amit | K36: =PRODUCT(E36,F36) -> 1800 | L36: =PRODUCT(K36,G36) -> 0 | M36: =K36-L36 -> 1800 | N36: =IF(M36>=50000,"High Value",IF(M36>=20000,"Medium Value","Low Value")) -> Low Value | O36: =IF(AND(E36>=5,G36>=15%),"High",IF(OR(E36>=3,G36>=10%),"Medium","Low")) -> Low | P36: =RIGHT(C36,3) -> 012 | Q36: =RIGHT(D36,3) -> 117 | R36: =PROPER(TRIM(J36)) -> Amit | S36: =TRIM(PROPER(I36)) -> South | T36: =IFERROR(VLOOKUP(D36,Product_Reference!$A$1:$F$26,2,0),"Not Found!!") -> Laptop Stand | U36: =IFERROR(VLOOKUP(D36,Product_Reference!$A$1:$F$26,3,0),"Not Found!!") -> Accessories | V36: =IFERROR(VLOOKUP(D36,Product_Reference!$A$1:$F$26,4,0),"Not Found!!") -> ErgoTech | W36: =IFERROR(VLOOKUP(D36,Product_Reference!$A$1:$F$26,5,0),"Not Found!!") -> PQR Ltd | X36: =IFERROR(VLOOKUP(D36,Product_Reference!$A$1:$F$26,6,0),"Not Found!!") -> 4 | AO36: P121
A37: ORD1036 | B37: 46041 | C37: C014 | D37: P123 | E37: 5 | F37: 2800 | G37: 0 | H37: Net Banking | I37: South | J37: Neha | K37: =PRODUCT(E37,F37) -> 14000 | L37: =PRODUCT(K37,G37) -> 0 | M37: =K37-L37 -> 14000 | N37: =IF(M37>=50000,"High Value",IF(M37>=20000,"Medium Value","Low Value")) -> Low Value | O37: =IF(AND(E37>=5,G37>=15%),"High",IF(OR(E37>=3,G37>=10%),"Medium","Low")) -> Medium | P37: =RIGHT(C37,3) -> 14 | Q37: =RIGHT(D37,3) -> 123 | R37: =PROPER(TRIM(J37)) -> Neha | S37: =TRIM(PROPER(I37)) -> South | T37: =IFERROR(VLOOKUP(D37,Product_Reference!$A$1:$F$26,2,0),"Not Found!!") -> Wi-Fi Range Extender | U37: =IFERROR(VLOOKUP(D37,Product_Reference!$A$1:$F$26,3,0),"Not Found!!") -> Networking | V37: =IFERROR(VLOOKUP(D37,Product_Reference!$A$1:$F$26,4,0),"Not Found!!") -> NetLink | W37: =IFERROR(VLOOKUP(D37,Product_Reference!$A$1:$F$26,5,0),"Not Found!!") -> XYZ Ltd | X37: =IFERROR(VLOOKUP(D37,Product_Reference!$A$1:$F$26,6,0),"Not Found!!") -> 4 | AA37: 9. Find the number of orders where Quantity is greater than or equal to 3 and Discount is greater than or equal to 10%. | AO37: P110
A38: ORD1037 | B38: 46097 | C38: C049 | D38: P124 | E38: 1 | F38: 2500 | G38: 0.2 | H38: UPI | I38: West | J38: Sneha | K38: =PRODUCT(E38,F38) -> 2500 | L38: =PRODUCT(K38,G38) -> 500 | M38: =K38-L38 -> 2000 | N38: =IF(M38>=50000,"High Value",IF(M38>=20000,"Medium Value","Low Value")) -> Low Value | O38: =IF(AND(E38>=5,G38>=15%),"High",IF(OR(E38>=3,G38>=10%),"Medium","Low")) -> Medium | P38: =RIGHT(C38,3) -> 049 | Q38: =RIGHT(D38,3) -> 124 | R38: =PROPER(TRIM(J38)) -> Sneha | S38: =TRIM(PROPER(I38)) -> West | T38: =IFERROR(VLOOKUP(D38,Product_Reference!$A$1:$F$26,2,0),"Not Found!!") -> Tablet Keyboard | U38: =IFERROR(VLOOKUP(D38,Product_Reference!$A$1:$F$26,3,0),"Not Found!!") -> Accessories | V38: =IFERROR(VLOOKUP(D38,Product_Reference!$A$1:$F$26,4,0),"Not Found!!") -> KeyMaster | W38: =IFERROR(VLOOKUP(D38,Product_Reference!$A$1:$F$26,5,0),"Not Found!!") -> PQR Ltd | X38: =IFERROR(VLOOKUP(D38,Product_Reference!$A$1:$F$26,6,0),"Not Found!!") -> 3.8 | AO38: P114
A39: ORD1038 | B39: 46047 | C39: C029 | D39: P103 | E39: 5 | F39: 65000 | G39: 0.08 | H39: UPI | I39: West | J39: Priya | K39: =PRODUCT(E39,F39) -> 325000 | L39: =PRODUCT(K39,G39) -> 26000 | M39: =K39-L39 -> 299000 | N39: =IF(M39>=50000,"High Value",IF(M39>=20000,"Medium Value","Low Value")) -> High Value | O39: =IF(AND(E39>=5,G39>=15%),"High",IF(OR(E39>=3,G39>=10%),"Medium","Low")) -> Medium | P39: =RIGHT(C39,3) -> 029 | Q39: =RIGHT(D39,3) -> 103 | R39: =PROPER(TRIM(J39)) -> Priya | S39: =TRIM(PROPER(I39)) -> West | T39: =IFERROR(VLOOKUP(D39,Product_Reference!$A$1:$F$26,2,0),"Not Found!!") -> Smartphone X | U39: =IFERROR(VLOOKUP(D39,Product_Reference!$A$1:$F$26,3,0),"Not Found!!") -> Electronics | V39: =IFERROR(VLOOKUP(D39,Product_Reference!$A$1:$F$26,4,0),"Not Found!!") -> MobileMax | W39: =IFERROR(VLOOKUP(D39,Product_Reference!$A$1:$F$26,5,0),"Not Found!!") -> ABC Ltd | X39: =IFERROR(VLOOKUP(D39,Product_Reference!$A$1:$F$26,6,0),"Not Found!!") -> 4.6 | AA39: No. of Orders | AB39: =COUNTIFS(E2:E151,">=3",G2:G151,">=10%") -> 40 | AO39: P115
A40: ORD1039 | B40: 46102 | C40: C041 | D40: P102 | E40: 3 | F40: 1200 | G40: 0.08 | H40: UPI | I40: South | J40: Rahul | K40: =PRODUCT(E40,F40) -> 3600 | L40: =PRODUCT(K40,G40) -> 288 | M40: =K40-L40 -> 3312 | N40: =IF(M40>=50000,"High Value",IF(M40>=20000,"Medium Value","Low Value")) -> Low Value | O40: =IF(AND(E40>=5,G40>=15%),"High",IF(OR(E40>=3,G40>=10%),"Medium","Low")) -> Medium | P40: =RIGHT(C40,3) -> 041 | Q40: =RIGHT(D40,3) -> 102 | R40: =PROPER(TRIM(J40)) -> Rahul | S40: =TRIM(PROPER(I40)) -> South | T40: =IFERROR(VLOOKUP(D40,Product_Reference!$A$1:$F$26,2,0),"Not Found!!") -> Wireless Mouse | U40: =IFERROR(VLOOKUP(D40,Product_Reference!$A$1:$F$26,3,0),"Not Found!!") -> Accessories | V40: =IFERROR(VLOOKUP(D40,Product_Reference!$A$1:$F$26,4,0),"Not Found!!") -> ClickTech | W40: =IFERROR(VLOOKUP(D40,Product_Reference!$A$1:$F$26,5,0),"Not Found!!") -> XYZ Ltd | X40: =IFERROR(VLOOKUP(D40,Product_Reference!$A$1:$F$26,6,0),"Not Found!!") -> 4.2 | AO40: P118
...

Sheet Product_Reference
A1: Product_ID | B1: Product_Name | C1: Category | D1: Brand | E1: Supplier | F1: Product_Rating
A2: P101 | B2: Laptop Pro 14 | C2: Electronics | D2: TechPro | E2: ABC Ltd | F2: 4.5
A3: P102 | B3: Wireless Mouse | C3: Accessories | D3: ClickTech | E3: XYZ Ltd | F3: 4.2
A4: P103 | B4: Smartphone X | C4: Electronics | D4: MobileMax | E4: ABC Ltd | F4: 4.6
A5: P104 | B5: Tablet 10 | C5: Electronics | D5: TabWorld | E5: PQR Ltd | F5: 4.1
A6: P105 | B6: Mechanical Keyboard | C6: Accessories | D6: KeyMaster | E6: XYZ Ltd | F6: 4.4
A7: P106 | B7: Bluetooth Speaker | C7: Audio | D7: SoundMax | E7: LMN Ltd | F7: 3.9
A8: P107 | B8: USB-C Hub | C8: Accessories | D8: ConnectPro | E8: PQR Ltd | F8: 4.3
A9: P108 | B9: Smart Watch | C9: Wearables | D9: FitTech | E9: ABC Ltd | F9: 4
A10: P109 | B10: Noise Cancelling Headphones | C10: Audio | D10: SoundMax | E10: LMN Ltd | F10: 4.7
A11: P110 | B11: External SSD 1TB | C11: Storage | D11: DataDrive | E11: PQR Ltd | F11: 4.5
A12: P111 | B12: Gaming Monitor 24 | C12: Electronics | D12: ViewMax | E12: XYZ Ltd | F12: 4.2
A13: P112 | B13: Webcam HD | C13: Accessories | D13: VisionTech | E13: ABC Ltd | F13: 3.8
... A26: P125 | B26: Laser Printer | C26: Office Equipment | D26: PrintPro | E26: ABC Ltd | F26: 4.2
